<?xml version="1.0" ?>
<!-- =================================================================================== -->
<!-- |    This document was autogenerated by xacro from /data/ros/ros_catkin_ws/src/moveit_resources/prbt_support/urdf/prbt.xacro | -->
<!-- |    EDITING THIS FILE BY HAND IS NOT RECOMMENDED                                 | -->
<!-- =================================================================================== -->
<!--
Copyright (c) 2018 Pilz GmbH & Co. KG

Licensed under the Apache License, Version 2.0 (the "License");
you may not use this file except in compliance with the License.
You may obtain a copy of the License at

    http://www.apache.org/licenses/LICENSE-2.0

Unless required by applicable law or agreed to in writing, software
distributed under the License is distributed on an "AS IS" BASIS,
WITHOUT WARRANTIES OR CONDITIONS OF ANY KIND, either express or implied.
See the License for the specific language governing permissions and
limitations under the License.
-->
<robot name="prbt">
  <!-- robot foot link -->
  <link name="prbt_base_link">
    <inertial>
      <mass value="2.4"/>
      <inertia ixx="0" ixy="0" ixz="0" iyy="0" iyz="0" izz="0"/>
    </inertial>
    <visual>
      <origin rpy="0 0 0" xyz="0 0 0"/>
      <geometry>
        <mesh filename="package://moveit_resources_prbt_support/meshes/foot.dae"/>
      </geometry>
    </visual>
    <collision>
      <origin rpy="3.141592653589793 0 0" xyz="0 0 0.065"/>
      <geometry>
        <cylinder length="0.13" radius="0.09275"/>
      </geometry>
    </collision>
  </link>
  <!-- arm 1 joint -->
  <joint name="prbt_joint_1" type="revolute">
    <origin rpy="0 0 -3.141592653589793" xyz="0 0 0.2604"/>
    <parent link="prbt_base_link"/>
    <child link="prbt_link_1"/>
    <axis xyz="0 0 1"/>
    <limit effort="370" lower="-2.96706" upper="2.96706" velocity="1.57"/>
    <dynamics damping="15.0" friction="11"/>
  </joint>
  <!-- arm 1 link -->
  <link name="prbt_link_1">
    <inertial>
      <mass value="7.1"/>
      <origin xyz="0 -0.026 -0.051"/>
      <inertia ixx="3.53e-2" ixy="0" ixz="0" iyy="3.01e-2" iyz="9.04e-3" izz="1.87e-2"/>
    </inertial>
    <visual>
      <origin rpy="0 0 0" xyz="0 0 0"/>
      <geometry>
        <mesh filename="package://moveit_resources_prbt_support/meshes/link_1.dae"/>
      </geometry>
    </visual>
    <collision>
      <origin rpy="0 0 0" xyz="0 0 -0.08"/>
      <geometry>
        <cylinder length="0.10" radius="0.07"/>
      </geometry>
    </collision>
    <collision>
      <origin rpy="0 0 0" xyz="0 0 0"/>
      <geometry>
        <sphere radius="0.09"/>
      </geometry>
    </collision>
    <collision>
      <origin rpy="0 1.5707963267948966 1.5707963267948966" xyz="0 -0.10 0"/>
      <geometry>
        <cylinder length="0.10" radius="0.065"/>
      </geometry>
    </collision>
  </link>
  <!-- joint between arm_1_link and arm_2_link -->
  <joint name="prbt_joint_2" type="revolute">
    <origin rpy="1.5707963267948966 0 0" xyz="0 0 0"/>
    <parent link="prbt_link_1"/>
    <child link="prbt_link_2"/>
    <axis xyz="0 0 1"/>
    <limit effort="370" lower="-2.53073" upper="2.53073" velocity="1.57"/>
    <dynamics damping="12.0" friction="10.0"/>
  </joint>
  <link name="prbt_link_2">
    <inertial>
      <mass value="1.7"/>
      <origin xyz="0 0.162 0.134"/>
      <inertia ixx="3.58e-2" ixy="0" ixz="0" iyy="3.22e-3" iyz="-1.45e-3" izz="3.66e-2"/>
    </inertial>
    <visual name="first">
      <origin rpy="0 0 0" xyz="0 0 0"/>
      <geometry>
        <mesh filename="package://moveit_resources_prbt_support/meshes/link_2.dae"/>
      </geometry>
    </visual>
    <collision>
      <origin rpy="0.17453292519943295 0 0" xyz="0 0.15 0.145"/>
      <geometry>
        <box size="0.121 0.27 0.065"/>
      </geometry>
    </collision>
    <collision>
      <origin rpy="-0.4487989505128276 0 0" xyz="0 0.3 0.145"/>
      <geometry>
        <box size="0.11 0.1 0.075"/>
      </geometry>
    </collision>
  </link>
  <!-- joint between arm_2_link and arm_3_link -->
  <joint name="prbt_joint_3" type="revolute">
    <origin rpy="0 3.141592653589793 0" xyz="0 0.35 0"/>
    <parent link="prbt_link_2"/>
    <child link="prbt_link_3"/>
    <axis xyz="0 0 1"/>
    <limit effort="176" lower="-2.35620" upper="2.35620" velocity="1.57"/>
    <dynamics damping="4.5" friction="4.5"/>
  </joint>
  <link name="prbt_link_3">
    <inertial>
      <mass value="4.8"/>
      <origin xyz="0 0.043 -0.027"/>
      <inertia ixx="2.06e-2" ixy="0" ixz="0" iyy="1.08e-2" iyz="-5.36e-3" izz="1.63e-2"/>
    </inertial>
    <visual>
      <origin rpy="0 0 0" xyz="0 0 0"/>
      <geometry>
        <mesh filename="package://moveit_resources_prbt_support/meshes/link_3.dae"/>
      </geometry>
    </visual>
    <collision>
      <origin rpy="0 0 0" xyz="0 0 -0.11"/>
      <geometry>
        <cylinder length="0.10" radius="0.06"/>
      </geometry>
    </collision>
    <collision>
      <origin rpy="0 0 0" xyz="0 0 0"/>
      <geometry>
        <sphere radius="0.085"/>
      </geometry>
    </collision>
    <collision>
      <origin rpy="0 1.5707963267948966 1.5707963267948966" xyz="0 0.10 0"/>
      <geometry>
        <cylinder length="0.10" radius="0.065"/>
      </geometry>
    </collision>
  </link>
  <!-- joint between arm_3_link and arm_4_link -->
  <joint name="prbt_joint_4" type="revolute">
    <origin rpy="-1.5707963267948966 3.141592653589793 0" xyz="0 0 0"/>
    <parent link="prbt_link_3"/>
    <child link="prbt_link_4"/>
    <axis xyz="0 0 1"/>
    <limit effort="176" lower="-2.96706" upper="2.96706" velocity="1.57"/>
    <dynamics damping="4.2" friction="3.8"/>
  </joint>
  <link name="prbt_link_4">
    <inertial>
      <mass value="0.9"/>
      <origin xyz="0 -0.061 0.204"/>
      <inertia ixx="6.79e-3" ixy="0" ixz="0" iyy="4.91e-3" iyz="2.67e-3" izz="3.40e-3"/>
    </inertial>
    <visual>
      <origin rpy="0 0 0" xyz="0 0 0"/>
      <geometry>
        <mesh filename="package://moveit_resources_prbt_support/meshes/link_4.dae"/>
      </geometry>
    </visual>
    <collision>
      <origin rpy="0.966643893412244 0 0" xyz="0 -0.04 0.162"/>
      <geometry>
        <box size="0.121 0.08 0.17"/>
      </geometry>
    </collision>
    <collision>
      <origin rpy="-0.10471975511965977 0 0" xyz="0 -0.115 0.25"/>
      <geometry>
        <box size="0.09 0.06 0.12"/>
      </geometry>
    </collision>
  </link>
  <!-- joint between arm_4_link and arm_5_link -->
  <joint name="prbt_joint_5" type="revolute">
    <origin rpy="1.5707963267948966 0 3.141592653589793" xyz="0 0 0.307"/>
    <parent link="prbt_link_4"/>
    <child link="prbt_link_5"/>
    <axis xyz="0 0 1"/>
    <limit effort="41.6" lower="-2.96706" upper="2.96706" velocity="1.57"/>
    <dynamics damping="1.5" friction="3.5"/>
  </joint>
  <link name="prbt_link_5">
    <inertial>
      <mass value="2.6"/>
      <origin xyz="-0.001 0.021 -0.032"/>
      <inertia ixx="7.37e-3" ixy="4.78e-6" ixz="6.00e-5" iyy="5.87e-3" iyz="-1.71e-3" izz="3.96e-3"/>
    </inertial>
    <visual>
      <origin rpy="0 0 0" xyz="0 0 0"/>
      <geometry>
        <mesh filename="package://moveit_resources_prbt_support/meshes/link_5.dae"/>
      </geometry>
    </visual>
    <collision>
      <origin rpy="0 0 0" xyz="0 0 -0.095"/>
      <geometry>
        <cylinder length="0.08" radius="0.045"/>
      </geometry>
    </collision>
    <collision>
      <origin rpy="0 0 0" xyz="0 0 -0.06"/>
      <geometry>
        <cylinder length="0.04" radius="0.0545"/>
      </geometry>
    </collision>
    <collision>
      <origin rpy="0 0 0" xyz="0 0 0"/>
      <geometry>
        <sphere radius="0.07"/>
      </geometry>
    </collision>
    <collision>
      <origin rpy="0 1.5707963267948966 1.5707963267948966" xyz="0 0.05 0"/>
      <geometry>
        <cylinder length="0.03" radius="0.05"/>
      </geometry>
    </collision>
    <collision>
      <origin rpy="0 1.5707963267948966 1.5707963267948966" xyz="0 0.05 0"/>
      <geometry>
        <cylinder length="0.049" radius="0.0435"/>
      </geometry>
    </collision>
  </link>
  <!-- joint between arm_5_link and flange -->
  <joint name="prbt_joint_6" type="revolute">
    <origin rpy="-1.5707963267948966 0 0" xyz="0 0.084 0"/>
    <parent link="prbt_link_5"/>
    <child link="prbt_flange"/>
    <axis xyz="0 0 1"/>
    <limit effort="20.1" lower="-3.12414" upper="3.12414" velocity="1.57"/>
    <dynamics damping="4.5" friction="7.0"/>
  </joint>
  <!-- Flange -->
  <link name="prbt_flange">
    <inertial>
      <mass value="0.02"/>
      <origin xyz="0 0 0"/>
      <inertia ixx="0" ixy="0" ixz="0" iyy="0" iyz="0" izz="0"/>
    </inertial>
    <visual>
      <origin rpy="0 0 0" xyz="0 0 0"/>
      <geometry>
        <mesh filename="package://moveit_resources_prbt_support/meshes/flange.dae"/>
      </geometry>
    </visual>
    <collision>
      <origin rpy="0 0 0" xyz="0 0 -0.0035"/>
      <geometry>
        <cylinder length="0.02" radius="0.0331"/>
      </geometry>
    </collision>
  </link>
  <!-- ROS-Industrial 'base' frame: base_link to robot world coordinate sytem transform -->
  <link name="prbt_base"/>
  <joint name="prbt_base_link-base" type="fixed">
    <origin rpy="0 0 0" xyz="0 0 0"/>
    <parent link="prbt_base_link"/>
    <child link="prbt_base"/>
  </joint>
  <!-- ROS-Industrial 'tool0' frame: all-zeros tool frame -->
  <link name="prbt_tool0"/>
  <joint name="prbt_flange-tool0" type="fixed">
    <origin rpy="0 0 0" xyz="0 0 0"/>
    <parent link="prbt_flange"/>
    <child link="prbt_tool0"/>
  </joint>
  <!-- transmissions for gazebo -->
  <transmission name="prbt_joint_1_trans">
    <type>transmission_interface/SimpleTransmission</type>
    <joint name="prbt_joint_1">
      <hardwareInterface>hardware_interface/PositionJointInterface</hardwareInterface>
    </joint>
    <actuator name="prbt_joint_1_motor"/>
  </transmission>
  <transmission name="prbt_joint_2_trans">
    <type>transmission_interface/SimpleTransmission</type>
    <joint name="prbt_joint_2">
      <hardwareInterface>hardware_interface/PositionJointInterface</hardwareInterface>
    </joint>
    <actuator name="prbt_joint_2_motor"/>
  </transmission>
  <transmission name="prbt_joint_3_trans">
    <type>transmission_interface/SimpleTransmission</type>
    <joint name="prbt_joint_3">
      <hardwareInterface>hardware_interface/PositionJointInterface</hardwareInterface>
    </joint>
    <actuator name="prbt_joint_3_motor"/>
  </transmission>
  <transmission name="prbt_joint_4_trans">
    <type>transmission_interface/SimpleTransmission</type>
    <joint name="prbt_joint_4">
      <hardwareInterface>hardware_interface/PositionJointInterface</hardwareInterface>
    </joint>
    <actuator name="prbt_joint_4_motor"/>
  </transmission>
  <transmission name="prbt_joint_5_trans">
    <type>transmission_interface/SimpleTransmission</type>
    <joint name="prbt_joint_5">
      <hardwareInterface>hardware_interface/PositionJointInterface</hardwareInterface>
    </joint>
    <actuator name="prbt_joint_5_motor"/>
  </transmission>
  <transmission name="prbt_joint_6_trans">
    <type>transmission_interface/SimpleTransmission</type>
    <joint name="prbt_joint_6">
      <hardwareInterface>hardware_interface/PositionJointInterface</hardwareInterface>
    </joint>
    <actuator name="prbt_joint_6_motor"/>
  </transmission>
  <gazebo>
    <plugin filename="libgazebo_ros_control.so" name="gazebo_ros_control">
      <robotNamespace>prbt</robotNamespace>
      <robotSimType>gazebo_ros_control/DefaultRobotHWSim</robotSimType>
      <legacyModeNS>false</legacyModeNS>
      <!-- Only used from ros-kinetic-gazebo-ros-control 2.5.18 -->
    </plugin>
  </gazebo>
  <gazebo reference="prbt_joint_1">
    <provideFeedback>true</provideFeedback>
  </gazebo>
  <gazebo>
    <plugin filename="libgazebo_ros_ft_sensor.so" name="ft_sensor">
      <updateRate>100.0</updateRate>
      <topicName>prbt/ft_sensor/joint_1</topicName>
      <jointName>prbt_joint_1</jointName>
    </plugin>
  </gazebo>
  <gazebo reference="prbt_joint_2">
    <provideFeedback>true</provideFeedback>
  </gazebo>
  <gazebo>
    <plugin filename="libgazebo_ros_ft_sensor.so" name="ft_sensor">
      <updateRate>100.0</updateRate>
      <topicName>prbt/ft_sensor/joint_2</topicName>
      <jointName>prbt_joint_2</jointName>
    </plugin>
  </gazebo>
  <gazebo reference="prbt_joint_3">
    <provideFeedback>true</provideFeedback>
  </gazebo>
  <gazebo>
    <plugin filename="libgazebo_ros_ft_sensor.so" name="ft_sensor">
      <updateRate>100.0</updateRate>
      <topicName>prbt/ft_sensor/joint_3</topicName>
      <jointName>prbt_joint_3</jointName>
    </plugin>
  </gazebo>
  <gazebo reference="prbt_joint_4">
    <provideFeedback>true</provideFeedback>
  </gazebo>
  <gazebo>
    <plugin filename="libgazebo_ros_ft_sensor.so" name="ft_sensor">
      <updateRate>100.0</updateRate>
      <topicName>prbt/ft_sensor/joint_4</topicName>
      <jointName>prbt_joint_4</jointName>
    </plugin>
  </gazebo>
  <gazebo reference="prbt_joint_5">
    <provideFeedback>true</provideFeedback>
  </gazebo>
  <gazebo>
    <plugin filename="libgazebo_ros_ft_sensor.so" name="ft_sensor">
      <updateRate>100.0</updateRate>
      <topicName>prbt/ft_sensor/joint_5</topicName>
      <jointName>prbt_joint_5</jointName>
    </plugin>
  </gazebo>
  <gazebo reference="prbt_joint_6">
    <provideFeedback>true</provideFeedback>
  </gazebo>
  <gazebo>
    <plugin filename="libgazebo_ros_ft_sensor.so" name="ft_sensor">
      <updateRate>100.0</updateRate>
      <topicName>prbt/ft_sensor/joint_6</topicName>
      <jointName>prbt_joint_6</jointName>
    </plugin>
  </gazebo>
  <link name="world"/>
  <joint name="world-base_link-fixed" type="fixed">
    <parent link="world"/>
    <child link="prbt_base_link"/>
  </joint>
  <!-- TCP -->
  <joint name="prbt_fixed_joint_tcp" type="fixed">
    <origin rpy="0 0 0" xyz="0 0 0"/>
    <!-- tcp offset from last link -->
    <parent link="prbt_flange"/>
    <child link="prbt_tcp"/>
  </joint>
  <link name="prbt_tcp"/>
</robot>
